{
 "cells": [
  {
   "cell_type": "code",
   "execution_count": 2,
   "metadata": {},
   "outputs": [
    {
     "name": "stdout",
     "output_type": "stream",
     "text": [
      "Found 16347 images belonging to 24 classes.\n",
      "Found 4195 images belonging to 24 classes.\n",
      "Number of training samples: 511\n",
      "Number of test samples: 132\n"
     ]
    }
   ],
   "source": [
    "import tensorflow as tf\n",
    "from tensorflow.keras.preprocessing.image import ImageDataGenerator\n",
    "\n",
    "# Define the paths to the training and test data\n",
    "train_data_path = \"train\"\n",
    "test_data_path = \"test\"\n",
    "\n",
    "# Create a training data generator\n",
    "train_datagen = ImageDataGenerator(\n",
    "    rescale=1.0 / 255.0,\n",
    "    rotation_range=20,\n",
    "    width_shift_range=0.2,\n",
    "    height_shift_range=0.2,\n",
    "    shear_range=0.2,\n",
    "    zoom_range=0.2,\n",
    "    horizontal_flip=True,\n",
    ")\n",
    "\n",
    "# Create a test data generator\n",
    "test_datagen = ImageDataGenerator(rescale=1.0 / 255.0)\n",
    "\n",
    "# Load the training and test data\n",
    "train_images = train_datagen.flow_from_directory(\n",
    "    train_data_path,\n",
    "    target_size=(224, 224),\n",
    "    batch_size=32,\n",
    "    class_mode=\"categorical\",\n",
    ")\n",
    "\n",
    "test_images = test_datagen.flow_from_directory(\n",
    "    test_data_path,\n",
    "    target_size=(224, 224),\n",
    "    batch_size=32,\n",
    "    class_mode=\"categorical\",\n",
    ")\n",
    "\n",
    "# Print the number of training and test samples\n",
    "print(\"Number of training samples:\", len(train_images))\n",
    "print(\"Number of test samples:\", len(test_images))\n"
   ]
  },
  {
   "cell_type": "code",
   "execution_count": 3,
   "metadata": {},
   "outputs": [
    {
     "name": "stdout",
     "output_type": "stream",
     "text": [
      "Found 16347 files belonging to 24 classes.\n",
      "Found 4195 files belonging to 24 classes.\n",
      "Epoch 1/10\n"
     ]
    },
    {
     "ename": "ResourceExhaustedError",
     "evalue": "Graph execution error:\n\nDetected at node 'sequential_1/vgg16/block1_conv2/Relu' defined at (most recent call last):\n    File \"c:\\Users\\ASUS\\AppData\\Local\\Programs\\Python\\Python39\\lib\\runpy.py\", line 197, in _run_module_as_main\n      return _run_code(code, main_globals, None,\n    File \"c:\\Users\\ASUS\\AppData\\Local\\Programs\\Python\\Python39\\lib\\runpy.py\", line 87, in _run_code\n      exec(code, run_globals)\n    File \"C:\\Users\\ASUS\\AppData\\Roaming\\Python\\Python39\\site-packages\\ipykernel_launcher.py\", line 17, in <module>\n      app.launch_new_instance()\n    File \"C:\\Users\\ASUS\\AppData\\Roaming\\Python\\Python39\\site-packages\\traitlets\\config\\application.py\", line 1046, in launch_instance\n      app.start()\n    File \"C:\\Users\\ASUS\\AppData\\Roaming\\Python\\Python39\\site-packages\\ipykernel\\kernelapp.py\", line 736, in start\n      self.io_loop.start()\n    File \"c:\\Users\\ASUS\\AppData\\Local\\Programs\\Python\\Python39\\lib\\site-packages\\tornado\\platform\\asyncio.py\", line 195, in start\n      self.asyncio_loop.run_forever()\n    File \"c:\\Users\\ASUS\\AppData\\Local\\Programs\\Python\\Python39\\lib\\asyncio\\base_events.py\", line 601, in run_forever\n      self._run_once()\n    File \"c:\\Users\\ASUS\\AppData\\Local\\Programs\\Python\\Python39\\lib\\asyncio\\base_events.py\", line 1905, in _run_once\n      handle._run()\n    File \"c:\\Users\\ASUS\\AppData\\Local\\Programs\\Python\\Python39\\lib\\asyncio\\events.py\", line 80, in _run\n      self._context.run(self._callback, *self._args)\n    File \"C:\\Users\\ASUS\\AppData\\Roaming\\Python\\Python39\\site-packages\\ipykernel\\kernelbase.py\", line 516, in dispatch_queue\n      await self.process_one()\n    File \"C:\\Users\\ASUS\\AppData\\Roaming\\Python\\Python39\\site-packages\\ipykernel\\kernelbase.py\", line 505, in process_one\n      await dispatch(*args)\n    File \"C:\\Users\\ASUS\\AppData\\Roaming\\Python\\Python39\\site-packages\\ipykernel\\kernelbase.py\", line 412, in dispatch_shell\n      await result\n    File \"C:\\Users\\ASUS\\AppData\\Roaming\\Python\\Python39\\site-packages\\ipykernel\\kernelbase.py\", line 740, in execute_request\n      reply_content = await reply_content\n    File \"C:\\Users\\ASUS\\AppData\\Roaming\\Python\\Python39\\site-packages\\ipykernel\\ipkernel.py\", line 422, in do_execute\n      res = shell.run_cell(\n    File \"C:\\Users\\ASUS\\AppData\\Roaming\\Python\\Python39\\site-packages\\ipykernel\\zmqshell.py\", line 546, in run_cell\n      return super().run_cell(*args, **kwargs)\n    File \"C:\\Users\\ASUS\\AppData\\Roaming\\Python\\Python39\\site-packages\\IPython\\core\\interactiveshell.py\", line 3024, in run_cell\n      result = self._run_cell(\n    File \"C:\\Users\\ASUS\\AppData\\Roaming\\Python\\Python39\\site-packages\\IPython\\core\\interactiveshell.py\", line 3079, in _run_cell\n      result = runner(coro)\n    File \"C:\\Users\\ASUS\\AppData\\Roaming\\Python\\Python39\\site-packages\\IPython\\core\\async_helpers.py\", line 129, in _pseudo_sync_runner\n      coro.send(None)\n    File \"C:\\Users\\ASUS\\AppData\\Roaming\\Python\\Python39\\site-packages\\IPython\\core\\interactiveshell.py\", line 3284, in run_cell_async\n      has_raised = await self.run_ast_nodes(code_ast.body, cell_name,\n    File \"C:\\Users\\ASUS\\AppData\\Roaming\\Python\\Python39\\site-packages\\IPython\\core\\interactiveshell.py\", line 3466, in run_ast_nodes\n      if await self.run_code(code, result, async_=asy):\n    File \"C:\\Users\\ASUS\\AppData\\Roaming\\Python\\Python39\\site-packages\\IPython\\core\\interactiveshell.py\", line 3526, in run_code\n      exec(code_obj, self.user_global_ns, self.user_ns)\n    File \"C:\\Users\\ASUS\\AppData\\Local\\Temp\\ipykernel_19196\\1256868408.py\", line 47, in <module>\n      model.fit(train_data, epochs=10)\n    File \"c:\\Users\\ASUS\\AppData\\Local\\Programs\\Python\\Python39\\lib\\site-packages\\keras\\utils\\traceback_utils.py\", line 65, in error_handler\n      return fn(*args, **kwargs)\n    File \"c:\\Users\\ASUS\\AppData\\Local\\Programs\\Python\\Python39\\lib\\site-packages\\keras\\engine\\training.py\", line 1564, in fit\n      tmp_logs = self.train_function(iterator)\n    File \"c:\\Users\\ASUS\\AppData\\Local\\Programs\\Python\\Python39\\lib\\site-packages\\keras\\engine\\training.py\", line 1160, in train_function\n      return step_function(self, iterator)\n    File \"c:\\Users\\ASUS\\AppData\\Local\\Programs\\Python\\Python39\\lib\\site-packages\\keras\\engine\\training.py\", line 1146, in step_function\n      outputs = model.distribute_strategy.run(run_step, args=(data,))\n    File \"c:\\Users\\ASUS\\AppData\\Local\\Programs\\Python\\Python39\\lib\\site-packages\\keras\\engine\\training.py\", line 1135, in run_step\n      outputs = model.train_step(data)\n    File \"c:\\Users\\ASUS\\AppData\\Local\\Programs\\Python\\Python39\\lib\\site-packages\\keras\\engine\\training.py\", line 993, in train_step\n      y_pred = self(x, training=True)\n    File \"c:\\Users\\ASUS\\AppData\\Local\\Programs\\Python\\Python39\\lib\\site-packages\\keras\\utils\\traceback_utils.py\", line 65, in error_handler\n      return fn(*args, **kwargs)\n    File \"c:\\Users\\ASUS\\AppData\\Local\\Programs\\Python\\Python39\\lib\\site-packages\\keras\\engine\\training.py\", line 557, in __call__\n      return super().__call__(*args, **kwargs)\n    File \"c:\\Users\\ASUS\\AppData\\Local\\Programs\\Python\\Python39\\lib\\site-packages\\keras\\utils\\traceback_utils.py\", line 65, in error_handler\n      return fn(*args, **kwargs)\n    File \"c:\\Users\\ASUS\\AppData\\Local\\Programs\\Python\\Python39\\lib\\site-packages\\keras\\engine\\base_layer.py\", line 1097, in __call__\n      outputs = call_fn(inputs, *args, **kwargs)\n    File \"c:\\Users\\ASUS\\AppData\\Local\\Programs\\Python\\Python39\\lib\\site-packages\\keras\\utils\\traceback_utils.py\", line 96, in error_handler\n      return fn(*args, **kwargs)\n    File \"c:\\Users\\ASUS\\AppData\\Local\\Programs\\Python\\Python39\\lib\\site-packages\\keras\\engine\\sequential.py\", line 410, in call\n      return super().call(inputs, training=training, mask=mask)\n    File \"c:\\Users\\ASUS\\AppData\\Local\\Programs\\Python\\Python39\\lib\\site-packages\\keras\\engine\\functional.py\", line 510, in call\n      return self._run_internal_graph(inputs, training=training, mask=mask)\n    File \"c:\\Users\\ASUS\\AppData\\Local\\Programs\\Python\\Python39\\lib\\site-packages\\keras\\engine\\functional.py\", line 667, in _run_internal_graph\n      outputs = node.layer(*args, **kwargs)\n    File \"c:\\Users\\ASUS\\AppData\\Local\\Programs\\Python\\Python39\\lib\\site-packages\\keras\\utils\\traceback_utils.py\", line 65, in error_handler\n      return fn(*args, **kwargs)\n    File \"c:\\Users\\ASUS\\AppData\\Local\\Programs\\Python\\Python39\\lib\\site-packages\\keras\\engine\\training.py\", line 557, in __call__\n      return super().__call__(*args, **kwargs)\n    File \"c:\\Users\\ASUS\\AppData\\Local\\Programs\\Python\\Python39\\lib\\site-packages\\keras\\utils\\traceback_utils.py\", line 65, in error_handler\n      return fn(*args, **kwargs)\n    File \"c:\\Users\\ASUS\\AppData\\Local\\Programs\\Python\\Python39\\lib\\site-packages\\keras\\engine\\base_layer.py\", line 1097, in __call__\n      outputs = call_fn(inputs, *args, **kwargs)\n    File \"c:\\Users\\ASUS\\AppData\\Local\\Programs\\Python\\Python39\\lib\\site-packages\\keras\\utils\\traceback_utils.py\", line 96, in error_handler\n      return fn(*args, **kwargs)\n    File \"c:\\Users\\ASUS\\AppData\\Local\\Programs\\Python\\Python39\\lib\\site-packages\\keras\\engine\\functional.py\", line 510, in call\n      return self._run_internal_graph(inputs, training=training, mask=mask)\n    File \"c:\\Users\\ASUS\\AppData\\Local\\Programs\\Python\\Python39\\lib\\site-packages\\keras\\engine\\functional.py\", line 667, in _run_internal_graph\n      outputs = node.layer(*args, **kwargs)\n    File \"c:\\Users\\ASUS\\AppData\\Local\\Programs\\Python\\Python39\\lib\\site-packages\\keras\\utils\\traceback_utils.py\", line 65, in error_handler\n      return fn(*args, **kwargs)\n    File \"c:\\Users\\ASUS\\AppData\\Local\\Programs\\Python\\Python39\\lib\\site-packages\\keras\\engine\\base_layer.py\", line 1097, in __call__\n      outputs = call_fn(inputs, *args, **kwargs)\n    File \"c:\\Users\\ASUS\\AppData\\Local\\Programs\\Python\\Python39\\lib\\site-packages\\keras\\utils\\traceback_utils.py\", line 96, in error_handler\n      return fn(*args, **kwargs)\n    File \"c:\\Users\\ASUS\\AppData\\Local\\Programs\\Python\\Python39\\lib\\site-packages\\keras\\layers\\convolutional\\base_conv.py\", line 314, in call\n      return self.activation(outputs)\n    File \"c:\\Users\\ASUS\\AppData\\Local\\Programs\\Python\\Python39\\lib\\site-packages\\keras\\activations.py\", line 317, in relu\n      return backend.relu(\n    File \"c:\\Users\\ASUS\\AppData\\Local\\Programs\\Python\\Python39\\lib\\site-packages\\keras\\backend.py\", line 5366, in relu\n      x = tf.nn.relu(x)\nNode: 'sequential_1/vgg16/block1_conv2/Relu'\nOOM when allocating tensor with shape[32,64,224,224] and type float on /job:localhost/replica:0/task:0/device:GPU:0 by allocator GPU_0_bfc\n\t [[{{node sequential_1/vgg16/block1_conv2/Relu}}]]\nHint: If you want to see a list of allocated tensors when OOM happens, add report_tensor_allocations_upon_oom to RunOptions for current allocation info. This isn't available when running in Eager mode.\n [Op:__inference_train_function_4037]",
     "output_type": "error",
     "traceback": [
      "\u001b[1;31m---------------------------------------------------------------------------\u001b[0m",
      "\u001b[1;31mResourceExhaustedError\u001b[0m                    Traceback (most recent call last)",
      "\u001b[1;32md:\\skindisease\\test.ipynb Cell 2\u001b[0m line \u001b[0;36m4\n\u001b[0;32m     <a href='vscode-notebook-cell:/d%3A/skindisease/test.ipynb#W1sZmlsZQ%3D%3D?line=39'>40</a>\u001b[0m model\u001b[39m.\u001b[39mcompile(\n\u001b[0;32m     <a href='vscode-notebook-cell:/d%3A/skindisease/test.ipynb#W1sZmlsZQ%3D%3D?line=40'>41</a>\u001b[0m     optimizer\u001b[39m=\u001b[39m\u001b[39m\"\u001b[39m\u001b[39madam\u001b[39m\u001b[39m\"\u001b[39m,\n\u001b[0;32m     <a href='vscode-notebook-cell:/d%3A/skindisease/test.ipynb#W1sZmlsZQ%3D%3D?line=41'>42</a>\u001b[0m     loss\u001b[39m=\u001b[39m\u001b[39m\"\u001b[39m\u001b[39mcategorical_crossentropy\u001b[39m\u001b[39m\"\u001b[39m,\n\u001b[0;32m     <a href='vscode-notebook-cell:/d%3A/skindisease/test.ipynb#W1sZmlsZQ%3D%3D?line=42'>43</a>\u001b[0m     metrics\u001b[39m=\u001b[39m[\u001b[39m\"\u001b[39m\u001b[39maccuracy\u001b[39m\u001b[39m\"\u001b[39m],\n\u001b[0;32m     <a href='vscode-notebook-cell:/d%3A/skindisease/test.ipynb#W1sZmlsZQ%3D%3D?line=43'>44</a>\u001b[0m )\n\u001b[0;32m     <a href='vscode-notebook-cell:/d%3A/skindisease/test.ipynb#W1sZmlsZQ%3D%3D?line=45'>46</a>\u001b[0m \u001b[39m# Train the model\u001b[39;00m\n\u001b[1;32m---> <a href='vscode-notebook-cell:/d%3A/skindisease/test.ipynb#W1sZmlsZQ%3D%3D?line=46'>47</a>\u001b[0m model\u001b[39m.\u001b[39;49mfit(train_data, epochs\u001b[39m=\u001b[39;49m\u001b[39m10\u001b[39;49m)\n\u001b[0;32m     <a href='vscode-notebook-cell:/d%3A/skindisease/test.ipynb#W1sZmlsZQ%3D%3D?line=48'>49</a>\u001b[0m \u001b[39m# Evaluate the model\u001b[39;00m\n\u001b[0;32m     <a href='vscode-notebook-cell:/d%3A/skindisease/test.ipynb#W1sZmlsZQ%3D%3D?line=49'>50</a>\u001b[0m test_loss, test_accuracy \u001b[39m=\u001b[39m model\u001b[39m.\u001b[39mevaluate(test_data)\n",
      "File \u001b[1;32mc:\\Users\\ASUS\\AppData\\Local\\Programs\\Python\\Python39\\lib\\site-packages\\keras\\utils\\traceback_utils.py:70\u001b[0m, in \u001b[0;36mfilter_traceback.<locals>.error_handler\u001b[1;34m(*args, **kwargs)\u001b[0m\n\u001b[0;32m     67\u001b[0m     filtered_tb \u001b[39m=\u001b[39m _process_traceback_frames(e\u001b[39m.\u001b[39m__traceback__)\n\u001b[0;32m     68\u001b[0m     \u001b[39m# To get the full stack trace, call:\u001b[39;00m\n\u001b[0;32m     69\u001b[0m     \u001b[39m# `tf.debugging.disable_traceback_filtering()`\u001b[39;00m\n\u001b[1;32m---> 70\u001b[0m     \u001b[39mraise\u001b[39;00m e\u001b[39m.\u001b[39mwith_traceback(filtered_tb) \u001b[39mfrom\u001b[39;00m \u001b[39mNone\u001b[39;00m\n\u001b[0;32m     71\u001b[0m \u001b[39mfinally\u001b[39;00m:\n\u001b[0;32m     72\u001b[0m     \u001b[39mdel\u001b[39;00m filtered_tb\n",
      "File \u001b[1;32m~\\AppData\\Roaming\\Python\\Python39\\site-packages\\tensorflow\\python\\eager\\execute.py:54\u001b[0m, in \u001b[0;36mquick_execute\u001b[1;34m(op_name, num_outputs, inputs, attrs, ctx, name)\u001b[0m\n\u001b[0;32m     52\u001b[0m \u001b[39mtry\u001b[39;00m:\n\u001b[0;32m     53\u001b[0m   ctx\u001b[39m.\u001b[39mensure_initialized()\n\u001b[1;32m---> 54\u001b[0m   tensors \u001b[39m=\u001b[39m pywrap_tfe\u001b[39m.\u001b[39mTFE_Py_Execute(ctx\u001b[39m.\u001b[39m_handle, device_name, op_name,\n\u001b[0;32m     55\u001b[0m                                       inputs, attrs, num_outputs)\n\u001b[0;32m     56\u001b[0m \u001b[39mexcept\u001b[39;00m core\u001b[39m.\u001b[39m_NotOkStatusException \u001b[39mas\u001b[39;00m e:\n\u001b[0;32m     57\u001b[0m   \u001b[39mif\u001b[39;00m name \u001b[39mis\u001b[39;00m \u001b[39mnot\u001b[39;00m \u001b[39mNone\u001b[39;00m:\n",
      "\u001b[1;31mResourceExhaustedError\u001b[0m: Graph execution error:\n\nDetected at node 'sequential_1/vgg16/block1_conv2/Relu' defined at (most recent call last):\n    File \"c:\\Users\\ASUS\\AppData\\Local\\Programs\\Python\\Python39\\lib\\runpy.py\", line 197, in _run_module_as_main\n      return _run_code(code, main_globals, None,\n    File \"c:\\Users\\ASUS\\AppData\\Local\\Programs\\Python\\Python39\\lib\\runpy.py\", line 87, in _run_code\n      exec(code, run_globals)\n    File \"C:\\Users\\ASUS\\AppData\\Roaming\\Python\\Python39\\site-packages\\ipykernel_launcher.py\", line 17, in <module>\n      app.launch_new_instance()\n    File \"C:\\Users\\ASUS\\AppData\\Roaming\\Python\\Python39\\site-packages\\traitlets\\config\\application.py\", line 1046, in launch_instance\n      app.start()\n    File \"C:\\Users\\ASUS\\AppData\\Roaming\\Python\\Python39\\site-packages\\ipykernel\\kernelapp.py\", line 736, in start\n      self.io_loop.start()\n    File \"c:\\Users\\ASUS\\AppData\\Local\\Programs\\Python\\Python39\\lib\\site-packages\\tornado\\platform\\asyncio.py\", line 195, in start\n      self.asyncio_loop.run_forever()\n    File \"c:\\Users\\ASUS\\AppData\\Local\\Programs\\Python\\Python39\\lib\\asyncio\\base_events.py\", line 601, in run_forever\n      self._run_once()\n    File \"c:\\Users\\ASUS\\AppData\\Local\\Programs\\Python\\Python39\\lib\\asyncio\\base_events.py\", line 1905, in _run_once\n      handle._run()\n    File \"c:\\Users\\ASUS\\AppData\\Local\\Programs\\Python\\Python39\\lib\\asyncio\\events.py\", line 80, in _run\n      self._context.run(self._callback, *self._args)\n    File \"C:\\Users\\ASUS\\AppData\\Roaming\\Python\\Python39\\site-packages\\ipykernel\\kernelbase.py\", line 516, in dispatch_queue\n      await self.process_one()\n    File \"C:\\Users\\ASUS\\AppData\\Roaming\\Python\\Python39\\site-packages\\ipykernel\\kernelbase.py\", line 505, in process_one\n      await dispatch(*args)\n    File \"C:\\Users\\ASUS\\AppData\\Roaming\\Python\\Python39\\site-packages\\ipykernel\\kernelbase.py\", line 412, in dispatch_shell\n      await result\n    File \"C:\\Users\\ASUS\\AppData\\Roaming\\Python\\Python39\\site-packages\\ipykernel\\kernelbase.py\", line 740, in execute_request\n      reply_content = await reply_content\n    File \"C:\\Users\\ASUS\\AppData\\Roaming\\Python\\Python39\\site-packages\\ipykernel\\ipkernel.py\", line 422, in do_execute\n      res = shell.run_cell(\n    File \"C:\\Users\\ASUS\\AppData\\Roaming\\Python\\Python39\\site-packages\\ipykernel\\zmqshell.py\", line 546, in run_cell\n      return super().run_cell(*args, **kwargs)\n    File \"C:\\Users\\ASUS\\AppData\\Roaming\\Python\\Python39\\site-packages\\IPython\\core\\interactiveshell.py\", line 3024, in run_cell\n      result = self._run_cell(\n    File \"C:\\Users\\ASUS\\AppData\\Roaming\\Python\\Python39\\site-packages\\IPython\\core\\interactiveshell.py\", line 3079, in _run_cell\n      result = runner(coro)\n    File \"C:\\Users\\ASUS\\AppData\\Roaming\\Python\\Python39\\site-packages\\IPython\\core\\async_helpers.py\", line 129, in _pseudo_sync_runner\n      coro.send(None)\n    File \"C:\\Users\\ASUS\\AppData\\Roaming\\Python\\Python39\\site-packages\\IPython\\core\\interactiveshell.py\", line 3284, in run_cell_async\n      has_raised = await self.run_ast_nodes(code_ast.body, cell_name,\n    File \"C:\\Users\\ASUS\\AppData\\Roaming\\Python\\Python39\\site-packages\\IPython\\core\\interactiveshell.py\", line 3466, in run_ast_nodes\n      if await self.run_code(code, result, async_=asy):\n    File \"C:\\Users\\ASUS\\AppData\\Roaming\\Python\\Python39\\site-packages\\IPython\\core\\interactiveshell.py\", line 3526, in run_code\n      exec(code_obj, self.user_global_ns, self.user_ns)\n    File \"C:\\Users\\ASUS\\AppData\\Local\\Temp\\ipykernel_19196\\1256868408.py\", line 47, in <module>\n      model.fit(train_data, epochs=10)\n    File \"c:\\Users\\ASUS\\AppData\\Local\\Programs\\Python\\Python39\\lib\\site-packages\\keras\\utils\\traceback_utils.py\", line 65, in error_handler\n      return fn(*args, **kwargs)\n    File \"c:\\Users\\ASUS\\AppData\\Local\\Programs\\Python\\Python39\\lib\\site-packages\\keras\\engine\\training.py\", line 1564, in fit\n      tmp_logs = self.train_function(iterator)\n    File \"c:\\Users\\ASUS\\AppData\\Local\\Programs\\Python\\Python39\\lib\\site-packages\\keras\\engine\\training.py\", line 1160, in train_function\n      return step_function(self, iterator)\n    File \"c:\\Users\\ASUS\\AppData\\Local\\Programs\\Python\\Python39\\lib\\site-packages\\keras\\engine\\training.py\", line 1146, in step_function\n      outputs = model.distribute_strategy.run(run_step, args=(data,))\n    File \"c:\\Users\\ASUS\\AppData\\Local\\Programs\\Python\\Python39\\lib\\site-packages\\keras\\engine\\training.py\", line 1135, in run_step\n      outputs = model.train_step(data)\n    File \"c:\\Users\\ASUS\\AppData\\Local\\Programs\\Python\\Python39\\lib\\site-packages\\keras\\engine\\training.py\", line 993, in train_step\n      y_pred = self(x, training=True)\n    File \"c:\\Users\\ASUS\\AppData\\Local\\Programs\\Python\\Python39\\lib\\site-packages\\keras\\utils\\traceback_utils.py\", line 65, in error_handler\n      return fn(*args, **kwargs)\n    File \"c:\\Users\\ASUS\\AppData\\Local\\Programs\\Python\\Python39\\lib\\site-packages\\keras\\engine\\training.py\", line 557, in __call__\n      return super().__call__(*args, **kwargs)\n    File \"c:\\Users\\ASUS\\AppData\\Local\\Programs\\Python\\Python39\\lib\\site-packages\\keras\\utils\\traceback_utils.py\", line 65, in error_handler\n      return fn(*args, **kwargs)\n    File \"c:\\Users\\ASUS\\AppData\\Local\\Programs\\Python\\Python39\\lib\\site-packages\\keras\\engine\\base_layer.py\", line 1097, in __call__\n      outputs = call_fn(inputs, *args, **kwargs)\n    File \"c:\\Users\\ASUS\\AppData\\Local\\Programs\\Python\\Python39\\lib\\site-packages\\keras\\utils\\traceback_utils.py\", line 96, in error_handler\n      return fn(*args, **kwargs)\n    File \"c:\\Users\\ASUS\\AppData\\Local\\Programs\\Python\\Python39\\lib\\site-packages\\keras\\engine\\sequential.py\", line 410, in call\n      return super().call(inputs, training=training, mask=mask)\n    File \"c:\\Users\\ASUS\\AppData\\Local\\Programs\\Python\\Python39\\lib\\site-packages\\keras\\engine\\functional.py\", line 510, in call\n      return self._run_internal_graph(inputs, training=training, mask=mask)\n    File \"c:\\Users\\ASUS\\AppData\\Local\\Programs\\Python\\Python39\\lib\\site-packages\\keras\\engine\\functional.py\", line 667, in _run_internal_graph\n      outputs = node.layer(*args, **kwargs)\n    File \"c:\\Users\\ASUS\\AppData\\Local\\Programs\\Python\\Python39\\lib\\site-packages\\keras\\utils\\traceback_utils.py\", line 65, in error_handler\n      return fn(*args, **kwargs)\n    File \"c:\\Users\\ASUS\\AppData\\Local\\Programs\\Python\\Python39\\lib\\site-packages\\keras\\engine\\training.py\", line 557, in __call__\n      return super().__call__(*args, **kwargs)\n    File \"c:\\Users\\ASUS\\AppData\\Local\\Programs\\Python\\Python39\\lib\\site-packages\\keras\\utils\\traceback_utils.py\", line 65, in error_handler\n      return fn(*args, **kwargs)\n    File \"c:\\Users\\ASUS\\AppData\\Local\\Programs\\Python\\Python39\\lib\\site-packages\\keras\\engine\\base_layer.py\", line 1097, in __call__\n      outputs = call_fn(inputs, *args, **kwargs)\n    File \"c:\\Users\\ASUS\\AppData\\Local\\Programs\\Python\\Python39\\lib\\site-packages\\keras\\utils\\traceback_utils.py\", line 96, in error_handler\n      return fn(*args, **kwargs)\n    File \"c:\\Users\\ASUS\\AppData\\Local\\Programs\\Python\\Python39\\lib\\site-packages\\keras\\engine\\functional.py\", line 510, in call\n      return self._run_internal_graph(inputs, training=training, mask=mask)\n    File \"c:\\Users\\ASUS\\AppData\\Local\\Programs\\Python\\Python39\\lib\\site-packages\\keras\\engine\\functional.py\", line 667, in _run_internal_graph\n      outputs = node.layer(*args, **kwargs)\n    File \"c:\\Users\\ASUS\\AppData\\Local\\Programs\\Python\\Python39\\lib\\site-packages\\keras\\utils\\traceback_utils.py\", line 65, in error_handler\n      return fn(*args, **kwargs)\n    File \"c:\\Users\\ASUS\\AppData\\Local\\Programs\\Python\\Python39\\lib\\site-packages\\keras\\engine\\base_layer.py\", line 1097, in __call__\n      outputs = call_fn(inputs, *args, **kwargs)\n    File \"c:\\Users\\ASUS\\AppData\\Local\\Programs\\Python\\Python39\\lib\\site-packages\\keras\\utils\\traceback_utils.py\", line 96, in error_handler\n      return fn(*args, **kwargs)\n    File \"c:\\Users\\ASUS\\AppData\\Local\\Programs\\Python\\Python39\\lib\\site-packages\\keras\\layers\\convolutional\\base_conv.py\", line 314, in call\n      return self.activation(outputs)\n    File \"c:\\Users\\ASUS\\AppData\\Local\\Programs\\Python\\Python39\\lib\\site-packages\\keras\\activations.py\", line 317, in relu\n      return backend.relu(\n    File \"c:\\Users\\ASUS\\AppData\\Local\\Programs\\Python\\Python39\\lib\\site-packages\\keras\\backend.py\", line 5366, in relu\n      x = tf.nn.relu(x)\nNode: 'sequential_1/vgg16/block1_conv2/Relu'\nOOM when allocating tensor with shape[32,64,224,224] and type float on /job:localhost/replica:0/task:0/device:GPU:0 by allocator GPU_0_bfc\n\t [[{{node sequential_1/vgg16/block1_conv2/Relu}}]]\nHint: If you want to see a list of allocated tensors when OOM happens, add report_tensor_allocations_upon_oom to RunOptions for current allocation info. This isn't available when running in Eager mode.\n [Op:__inference_train_function_4037]"
     ]
    }
   ],
   "source": [
    "import tensorflow as tf\n",
    "from tensorflow.keras.applications import VGG16\n",
    "from tensorflow.keras.layers import Flatten, Dense\n",
    "\n",
    "# Load the training and test data\n",
    "train_data = tf.keras.preprocessing.image_dataset_from_directory(\n",
    "    \"train\",\n",
    "    labels=\"inferred\",\n",
    "    label_mode=\"categorical\",\n",
    "    batch_size=32,\n",
    "    image_size=(224, 224),\n",
    ")\n",
    "\n",
    "test_data = tf.keras.preprocessing.image_dataset_from_directory(\n",
    "    \"test\",\n",
    "    labels=\"inferred\",\n",
    "    label_mode=\"categorical\",\n",
    "    batch_size=32,\n",
    "    image_size=(224, 224),\n",
    ")\n",
    "\n",
    "# Define the base VGG16 model\n",
    "base_model = VGG16(\n",
    "    weights=\"imagenet\",\n",
    "    include_top=False,\n",
    "    input_shape=(224, 224, 3),\n",
    ")\n",
    "\n",
    "# Create a new model by specifying the input and output layers\n",
    "model = tf.keras.Sequential()\n",
    "model.add(base_model)  # Add the VGG16 base model\n",
    "\n",
    "# Add a Flatten layer\n",
    "model.add(Flatten())\n",
    "\n",
    "# Add a Dense classification layer\n",
    "model.add(Dense(24, activation=\"softmax\"))\n",
    "\n",
    "# Compile the model\n",
    "model.compile(\n",
    "    optimizer=\"adam\",\n",
    "    loss=\"categorical_crossentropy\",\n",
    "    metrics=[\"accuracy\"],\n",
    ")\n",
    "\n",
    "# Train the model\n",
    "model.fit(train_data, epochs=10)\n",
    "\n",
    "# Evaluate the model\n",
    "test_loss, test_accuracy = model.evaluate(test_data)\n",
    "\n",
    "# Print the test accuracy\n",
    "print(\"Test accuracy:\", test_accuracy)\n"
   ]
  },
  {
   "cell_type": "code",
   "execution_count": null,
   "metadata": {},
   "outputs": [],
   "source": []
  },
  {
   "cell_type": "code",
   "execution_count": 9,
   "metadata": {},
   "outputs": [
    {
     "name": "stdout",
     "output_type": "stream",
     "text": [
      "Physical devices cannot be modified after being initialized\n",
      "Found 16347 files belonging to 24 classes.\n",
      "Found 4195 files belonging to 24 classes.\n",
      "Epoch 1/10\n"
     ]
    },
    {
     "ename": "ResourceExhaustedError",
     "evalue": "Graph execution error:\n\nDetected at node 'sequential_5/vgg16/block4_conv2/Relu' defined at (most recent call last):\n    File \"c:\\Users\\ASUS\\AppData\\Local\\Programs\\Python\\Python39\\lib\\runpy.py\", line 197, in _run_module_as_main\n      return _run_code(code, main_globals, None,\n    File \"c:\\Users\\ASUS\\AppData\\Local\\Programs\\Python\\Python39\\lib\\runpy.py\", line 87, in _run_code\n      exec(code, run_globals)\n    File \"C:\\Users\\ASUS\\AppData\\Roaming\\Python\\Python39\\site-packages\\ipykernel_launcher.py\", line 17, in <module>\n      app.launch_new_instance()\n    File \"C:\\Users\\ASUS\\AppData\\Roaming\\Python\\Python39\\site-packages\\traitlets\\config\\application.py\", line 1046, in launch_instance\n      app.start()\n    File \"C:\\Users\\ASUS\\AppData\\Roaming\\Python\\Python39\\site-packages\\ipykernel\\kernelapp.py\", line 736, in start\n      self.io_loop.start()\n    File \"c:\\Users\\ASUS\\AppData\\Local\\Programs\\Python\\Python39\\lib\\site-packages\\tornado\\platform\\asyncio.py\", line 195, in start\n      self.asyncio_loop.run_forever()\n    File \"c:\\Users\\ASUS\\AppData\\Local\\Programs\\Python\\Python39\\lib\\asyncio\\base_events.py\", line 601, in run_forever\n      self._run_once()\n    File \"c:\\Users\\ASUS\\AppData\\Local\\Programs\\Python\\Python39\\lib\\asyncio\\base_events.py\", line 1905, in _run_once\n      handle._run()\n    File \"c:\\Users\\ASUS\\AppData\\Local\\Programs\\Python\\Python39\\lib\\asyncio\\events.py\", line 80, in _run\n      self._context.run(self._callback, *self._args)\n    File \"C:\\Users\\ASUS\\AppData\\Roaming\\Python\\Python39\\site-packages\\ipykernel\\kernelbase.py\", line 516, in dispatch_queue\n      await self.process_one()\n    File \"C:\\Users\\ASUS\\AppData\\Roaming\\Python\\Python39\\site-packages\\ipykernel\\kernelbase.py\", line 505, in process_one\n      await dispatch(*args)\n    File \"C:\\Users\\ASUS\\AppData\\Roaming\\Python\\Python39\\site-packages\\ipykernel\\kernelbase.py\", line 412, in dispatch_shell\n      await result\n    File \"C:\\Users\\ASUS\\AppData\\Roaming\\Python\\Python39\\site-packages\\ipykernel\\kernelbase.py\", line 740, in execute_request\n      reply_content = await reply_content\n    File \"C:\\Users\\ASUS\\AppData\\Roaming\\Python\\Python39\\site-packages\\ipykernel\\ipkernel.py\", line 422, in do_execute\n      res = shell.run_cell(\n    File \"C:\\Users\\ASUS\\AppData\\Roaming\\Python\\Python39\\site-packages\\ipykernel\\zmqshell.py\", line 546, in run_cell\n      return super().run_cell(*args, **kwargs)\n    File \"C:\\Users\\ASUS\\AppData\\Roaming\\Python\\Python39\\site-packages\\IPython\\core\\interactiveshell.py\", line 3024, in run_cell\n      result = self._run_cell(\n    File \"C:\\Users\\ASUS\\AppData\\Roaming\\Python\\Python39\\site-packages\\IPython\\core\\interactiveshell.py\", line 3079, in _run_cell\n      result = runner(coro)\n    File \"C:\\Users\\ASUS\\AppData\\Roaming\\Python\\Python39\\site-packages\\IPython\\core\\async_helpers.py\", line 129, in _pseudo_sync_runner\n      coro.send(None)\n    File \"C:\\Users\\ASUS\\AppData\\Roaming\\Python\\Python39\\site-packages\\IPython\\core\\interactiveshell.py\", line 3284, in run_cell_async\n      has_raised = await self.run_ast_nodes(code_ast.body, cell_name,\n    File \"C:\\Users\\ASUS\\AppData\\Roaming\\Python\\Python39\\site-packages\\IPython\\core\\interactiveshell.py\", line 3466, in run_ast_nodes\n      if await self.run_code(code, result, async_=asy):\n    File \"C:\\Users\\ASUS\\AppData\\Roaming\\Python\\Python39\\site-packages\\IPython\\core\\interactiveshell.py\", line 3526, in run_code\n      exec(code_obj, self.user_global_ns, self.user_ns)\n    File \"C:\\Users\\ASUS\\AppData\\Local\\Temp\\ipykernel_19196\\3801555835.py\", line 63, in <module>\n      model.fit(train_data, epochs=10)\n    File \"c:\\Users\\ASUS\\AppData\\Local\\Programs\\Python\\Python39\\lib\\site-packages\\keras\\utils\\traceback_utils.py\", line 65, in error_handler\n      return fn(*args, **kwargs)\n    File \"c:\\Users\\ASUS\\AppData\\Local\\Programs\\Python\\Python39\\lib\\site-packages\\keras\\engine\\training.py\", line 1564, in fit\n      tmp_logs = self.train_function(iterator)\n    File \"c:\\Users\\ASUS\\AppData\\Local\\Programs\\Python\\Python39\\lib\\site-packages\\keras\\engine\\training.py\", line 1160, in train_function\n      return step_function(self, iterator)\n    File \"c:\\Users\\ASUS\\AppData\\Local\\Programs\\Python\\Python39\\lib\\site-packages\\keras\\engine\\training.py\", line 1146, in step_function\n      outputs = model.distribute_strategy.run(run_step, args=(data,))\n    File \"c:\\Users\\ASUS\\AppData\\Local\\Programs\\Python\\Python39\\lib\\site-packages\\keras\\engine\\training.py\", line 1135, in run_step\n      outputs = model.train_step(data)\n    File \"c:\\Users\\ASUS\\AppData\\Local\\Programs\\Python\\Python39\\lib\\site-packages\\keras\\engine\\training.py\", line 993, in train_step\n      y_pred = self(x, training=True)\n    File \"c:\\Users\\ASUS\\AppData\\Local\\Programs\\Python\\Python39\\lib\\site-packages\\keras\\utils\\traceback_utils.py\", line 65, in error_handler\n      return fn(*args, **kwargs)\n    File \"c:\\Users\\ASUS\\AppData\\Local\\Programs\\Python\\Python39\\lib\\site-packages\\keras\\engine\\training.py\", line 557, in __call__\n      return super().__call__(*args, **kwargs)\n    File \"c:\\Users\\ASUS\\AppData\\Local\\Programs\\Python\\Python39\\lib\\site-packages\\keras\\utils\\traceback_utils.py\", line 65, in error_handler\n      return fn(*args, **kwargs)\n    File \"c:\\Users\\ASUS\\AppData\\Local\\Programs\\Python\\Python39\\lib\\site-packages\\keras\\engine\\base_layer.py\", line 1097, in __call__\n      outputs = call_fn(inputs, *args, **kwargs)\n    File \"c:\\Users\\ASUS\\AppData\\Local\\Programs\\Python\\Python39\\lib\\site-packages\\keras\\utils\\traceback_utils.py\", line 96, in error_handler\n      return fn(*args, **kwargs)\n    File \"c:\\Users\\ASUS\\AppData\\Local\\Programs\\Python\\Python39\\lib\\site-packages\\keras\\engine\\sequential.py\", line 410, in call\n      return super().call(inputs, training=training, mask=mask)\n    File \"c:\\Users\\ASUS\\AppData\\Local\\Programs\\Python\\Python39\\lib\\site-packages\\keras\\engine\\functional.py\", line 510, in call\n      return self._run_internal_graph(inputs, training=training, mask=mask)\n    File \"c:\\Users\\ASUS\\AppData\\Local\\Programs\\Python\\Python39\\lib\\site-packages\\keras\\engine\\functional.py\", line 667, in _run_internal_graph\n      outputs = node.layer(*args, **kwargs)\n    File \"c:\\Users\\ASUS\\AppData\\Local\\Programs\\Python\\Python39\\lib\\site-packages\\keras\\utils\\traceback_utils.py\", line 65, in error_handler\n      return fn(*args, **kwargs)\n    File \"c:\\Users\\ASUS\\AppData\\Local\\Programs\\Python\\Python39\\lib\\site-packages\\keras\\engine\\training.py\", line 557, in __call__\n      return super().__call__(*args, **kwargs)\n    File \"c:\\Users\\ASUS\\AppData\\Local\\Programs\\Python\\Python39\\lib\\site-packages\\keras\\utils\\traceback_utils.py\", line 65, in error_handler\n      return fn(*args, **kwargs)\n    File \"c:\\Users\\ASUS\\AppData\\Local\\Programs\\Python\\Python39\\lib\\site-packages\\keras\\engine\\base_layer.py\", line 1097, in __call__\n      outputs = call_fn(inputs, *args, **kwargs)\n    File \"c:\\Users\\ASUS\\AppData\\Local\\Programs\\Python\\Python39\\lib\\site-packages\\keras\\utils\\traceback_utils.py\", line 96, in error_handler\n      return fn(*args, **kwargs)\n    File \"c:\\Users\\ASUS\\AppData\\Local\\Programs\\Python\\Python39\\lib\\site-packages\\keras\\engine\\functional.py\", line 510, in call\n      return self._run_internal_graph(inputs, training=training, mask=mask)\n    File \"c:\\Users\\ASUS\\AppData\\Local\\Programs\\Python\\Python39\\lib\\site-packages\\keras\\engine\\functional.py\", line 667, in _run_internal_graph\n      outputs = node.layer(*args, **kwargs)\n    File \"c:\\Users\\ASUS\\AppData\\Local\\Programs\\Python\\Python39\\lib\\site-packages\\keras\\utils\\traceback_utils.py\", line 65, in error_handler\n      return fn(*args, **kwargs)\n    File \"c:\\Users\\ASUS\\AppData\\Local\\Programs\\Python\\Python39\\lib\\site-packages\\keras\\engine\\base_layer.py\", line 1097, in __call__\n      outputs = call_fn(inputs, *args, **kwargs)\n    File \"c:\\Users\\ASUS\\AppData\\Local\\Programs\\Python\\Python39\\lib\\site-packages\\keras\\utils\\traceback_utils.py\", line 96, in error_handler\n      return fn(*args, **kwargs)\n    File \"c:\\Users\\ASUS\\AppData\\Local\\Programs\\Python\\Python39\\lib\\site-packages\\keras\\layers\\convolutional\\base_conv.py\", line 314, in call\n      return self.activation(outputs)\n    File \"c:\\Users\\ASUS\\AppData\\Local\\Programs\\Python\\Python39\\lib\\site-packages\\keras\\activations.py\", line 317, in relu\n      return backend.relu(\n    File \"c:\\Users\\ASUS\\AppData\\Local\\Programs\\Python\\Python39\\lib\\site-packages\\keras\\backend.py\", line 5366, in relu\n      x = tf.nn.relu(x)\nNode: 'sequential_5/vgg16/block4_conv2/Relu'\nOOM when allocating tensor with shape[8,512,28,28] and type float on /job:localhost/replica:0/task:0/device:GPU:0 by allocator GPU_0_bfc\n\t [[{{node sequential_5/vgg16/block4_conv2/Relu}}]]\nHint: If you want to see a list of allocated tensors when OOM happens, add report_tensor_allocations_upon_oom to RunOptions for current allocation info. This isn't available when running in Eager mode.\n [Op:__inference_train_function_12109]",
     "output_type": "error",
     "traceback": [
      "\u001b[1;31m---------------------------------------------------------------------------\u001b[0m",
      "\u001b[1;31mResourceExhaustedError\u001b[0m                    Traceback (most recent call last)",
      "\u001b[1;32md:\\skindisease\\test.ipynb Cell 4\u001b[0m line \u001b[0;36m6\n\u001b[0;32m     <a href='vscode-notebook-cell:/d%3A/skindisease/test.ipynb#W2sZmlsZQ%3D%3D?line=55'>56</a>\u001b[0m model\u001b[39m.\u001b[39mcompile(\n\u001b[0;32m     <a href='vscode-notebook-cell:/d%3A/skindisease/test.ipynb#W2sZmlsZQ%3D%3D?line=56'>57</a>\u001b[0m     optimizer\u001b[39m=\u001b[39m\u001b[39m\"\u001b[39m\u001b[39madam\u001b[39m\u001b[39m\"\u001b[39m,\n\u001b[0;32m     <a href='vscode-notebook-cell:/d%3A/skindisease/test.ipynb#W2sZmlsZQ%3D%3D?line=57'>58</a>\u001b[0m     loss\u001b[39m=\u001b[39m\u001b[39m\"\u001b[39m\u001b[39mcategorical_crossentropy\u001b[39m\u001b[39m\"\u001b[39m,\n\u001b[0;32m     <a href='vscode-notebook-cell:/d%3A/skindisease/test.ipynb#W2sZmlsZQ%3D%3D?line=58'>59</a>\u001b[0m     metrics\u001b[39m=\u001b[39m[\u001b[39m\"\u001b[39m\u001b[39maccuracy\u001b[39m\u001b[39m\"\u001b[39m],\n\u001b[0;32m     <a href='vscode-notebook-cell:/d%3A/skindisease/test.ipynb#W2sZmlsZQ%3D%3D?line=59'>60</a>\u001b[0m )\n\u001b[0;32m     <a href='vscode-notebook-cell:/d%3A/skindisease/test.ipynb#W2sZmlsZQ%3D%3D?line=61'>62</a>\u001b[0m \u001b[39m# Train the model\u001b[39;00m\n\u001b[1;32m---> <a href='vscode-notebook-cell:/d%3A/skindisease/test.ipynb#W2sZmlsZQ%3D%3D?line=62'>63</a>\u001b[0m model\u001b[39m.\u001b[39;49mfit(train_data, epochs\u001b[39m=\u001b[39;49m\u001b[39m10\u001b[39;49m)\n\u001b[0;32m     <a href='vscode-notebook-cell:/d%3A/skindisease/test.ipynb#W2sZmlsZQ%3D%3D?line=64'>65</a>\u001b[0m \u001b[39m# Evaluate the model\u001b[39;00m\n\u001b[0;32m     <a href='vscode-notebook-cell:/d%3A/skindisease/test.ipynb#W2sZmlsZQ%3D%3D?line=65'>66</a>\u001b[0m test_loss, test_accuracy \u001b[39m=\u001b[39m model\u001b[39m.\u001b[39mevaluate(test_data)\n",
      "File \u001b[1;32mc:\\Users\\ASUS\\AppData\\Local\\Programs\\Python\\Python39\\lib\\site-packages\\keras\\utils\\traceback_utils.py:70\u001b[0m, in \u001b[0;36mfilter_traceback.<locals>.error_handler\u001b[1;34m(*args, **kwargs)\u001b[0m\n\u001b[0;32m     67\u001b[0m     filtered_tb \u001b[39m=\u001b[39m _process_traceback_frames(e\u001b[39m.\u001b[39m__traceback__)\n\u001b[0;32m     68\u001b[0m     \u001b[39m# To get the full stack trace, call:\u001b[39;00m\n\u001b[0;32m     69\u001b[0m     \u001b[39m# `tf.debugging.disable_traceback_filtering()`\u001b[39;00m\n\u001b[1;32m---> 70\u001b[0m     \u001b[39mraise\u001b[39;00m e\u001b[39m.\u001b[39mwith_traceback(filtered_tb) \u001b[39mfrom\u001b[39;00m \u001b[39mNone\u001b[39;00m\n\u001b[0;32m     71\u001b[0m \u001b[39mfinally\u001b[39;00m:\n\u001b[0;32m     72\u001b[0m     \u001b[39mdel\u001b[39;00m filtered_tb\n",
      "File \u001b[1;32m~\\AppData\\Roaming\\Python\\Python39\\site-packages\\tensorflow\\python\\eager\\execute.py:54\u001b[0m, in \u001b[0;36mquick_execute\u001b[1;34m(op_name, num_outputs, inputs, attrs, ctx, name)\u001b[0m\n\u001b[0;32m     52\u001b[0m \u001b[39mtry\u001b[39;00m:\n\u001b[0;32m     53\u001b[0m   ctx\u001b[39m.\u001b[39mensure_initialized()\n\u001b[1;32m---> 54\u001b[0m   tensors \u001b[39m=\u001b[39m pywrap_tfe\u001b[39m.\u001b[39mTFE_Py_Execute(ctx\u001b[39m.\u001b[39m_handle, device_name, op_name,\n\u001b[0;32m     55\u001b[0m                                       inputs, attrs, num_outputs)\n\u001b[0;32m     56\u001b[0m \u001b[39mexcept\u001b[39;00m core\u001b[39m.\u001b[39m_NotOkStatusException \u001b[39mas\u001b[39;00m e:\n\u001b[0;32m     57\u001b[0m   \u001b[39mif\u001b[39;00m name \u001b[39mis\u001b[39;00m \u001b[39mnot\u001b[39;00m \u001b[39mNone\u001b[39;00m:\n",
      "\u001b[1;31mResourceExhaustedError\u001b[0m: Graph execution error:\n\nDetected at node 'sequential_5/vgg16/block4_conv2/Relu' defined at (most recent call last):\n    File \"c:\\Users\\ASUS\\AppData\\Local\\Programs\\Python\\Python39\\lib\\runpy.py\", line 197, in _run_module_as_main\n      return _run_code(code, main_globals, None,\n    File \"c:\\Users\\ASUS\\AppData\\Local\\Programs\\Python\\Python39\\lib\\runpy.py\", line 87, in _run_code\n      exec(code, run_globals)\n    File \"C:\\Users\\ASUS\\AppData\\Roaming\\Python\\Python39\\site-packages\\ipykernel_launcher.py\", line 17, in <module>\n      app.launch_new_instance()\n    File \"C:\\Users\\ASUS\\AppData\\Roaming\\Python\\Python39\\site-packages\\traitlets\\config\\application.py\", line 1046, in launch_instance\n      app.start()\n    File \"C:\\Users\\ASUS\\AppData\\Roaming\\Python\\Python39\\site-packages\\ipykernel\\kernelapp.py\", line 736, in start\n      self.io_loop.start()\n    File \"c:\\Users\\ASUS\\AppData\\Local\\Programs\\Python\\Python39\\lib\\site-packages\\tornado\\platform\\asyncio.py\", line 195, in start\n      self.asyncio_loop.run_forever()\n    File \"c:\\Users\\ASUS\\AppData\\Local\\Programs\\Python\\Python39\\lib\\asyncio\\base_events.py\", line 601, in run_forever\n      self._run_once()\n    File \"c:\\Users\\ASUS\\AppData\\Local\\Programs\\Python\\Python39\\lib\\asyncio\\base_events.py\", line 1905, in _run_once\n      handle._run()\n    File \"c:\\Users\\ASUS\\AppData\\Local\\Programs\\Python\\Python39\\lib\\asyncio\\events.py\", line 80, in _run\n      self._context.run(self._callback, *self._args)\n    File \"C:\\Users\\ASUS\\AppData\\Roaming\\Python\\Python39\\site-packages\\ipykernel\\kernelbase.py\", line 516, in dispatch_queue\n      await self.process_one()\n    File \"C:\\Users\\ASUS\\AppData\\Roaming\\Python\\Python39\\site-packages\\ipykernel\\kernelbase.py\", line 505, in process_one\n      await dispatch(*args)\n    File \"C:\\Users\\ASUS\\AppData\\Roaming\\Python\\Python39\\site-packages\\ipykernel\\kernelbase.py\", line 412, in dispatch_shell\n      await result\n    File \"C:\\Users\\ASUS\\AppData\\Roaming\\Python\\Python39\\site-packages\\ipykernel\\kernelbase.py\", line 740, in execute_request\n      reply_content = await reply_content\n    File \"C:\\Users\\ASUS\\AppData\\Roaming\\Python\\Python39\\site-packages\\ipykernel\\ipkernel.py\", line 422, in do_execute\n      res = shell.run_cell(\n    File \"C:\\Users\\ASUS\\AppData\\Roaming\\Python\\Python39\\site-packages\\ipykernel\\zmqshell.py\", line 546, in run_cell\n      return super().run_cell(*args, **kwargs)\n    File \"C:\\Users\\ASUS\\AppData\\Roaming\\Python\\Python39\\site-packages\\IPython\\core\\interactiveshell.py\", line 3024, in run_cell\n      result = self._run_cell(\n    File \"C:\\Users\\ASUS\\AppData\\Roaming\\Python\\Python39\\site-packages\\IPython\\core\\interactiveshell.py\", line 3079, in _run_cell\n      result = runner(coro)\n    File \"C:\\Users\\ASUS\\AppData\\Roaming\\Python\\Python39\\site-packages\\IPython\\core\\async_helpers.py\", line 129, in _pseudo_sync_runner\n      coro.send(None)\n    File \"C:\\Users\\ASUS\\AppData\\Roaming\\Python\\Python39\\site-packages\\IPython\\core\\interactiveshell.py\", line 3284, in run_cell_async\n      has_raised = await self.run_ast_nodes(code_ast.body, cell_name,\n    File \"C:\\Users\\ASUS\\AppData\\Roaming\\Python\\Python39\\site-packages\\IPython\\core\\interactiveshell.py\", line 3466, in run_ast_nodes\n      if await self.run_code(code, result, async_=asy):\n    File \"C:\\Users\\ASUS\\AppData\\Roaming\\Python\\Python39\\site-packages\\IPython\\core\\interactiveshell.py\", line 3526, in run_code\n      exec(code_obj, self.user_global_ns, self.user_ns)\n    File \"C:\\Users\\ASUS\\AppData\\Local\\Temp\\ipykernel_19196\\3801555835.py\", line 63, in <module>\n      model.fit(train_data, epochs=10)\n    File \"c:\\Users\\ASUS\\AppData\\Local\\Programs\\Python\\Python39\\lib\\site-packages\\keras\\utils\\traceback_utils.py\", line 65, in error_handler\n      return fn(*args, **kwargs)\n    File \"c:\\Users\\ASUS\\AppData\\Local\\Programs\\Python\\Python39\\lib\\site-packages\\keras\\engine\\training.py\", line 1564, in fit\n      tmp_logs = self.train_function(iterator)\n    File \"c:\\Users\\ASUS\\AppData\\Local\\Programs\\Python\\Python39\\lib\\site-packages\\keras\\engine\\training.py\", line 1160, in train_function\n      return step_function(self, iterator)\n    File \"c:\\Users\\ASUS\\AppData\\Local\\Programs\\Python\\Python39\\lib\\site-packages\\keras\\engine\\training.py\", line 1146, in step_function\n      outputs = model.distribute_strategy.run(run_step, args=(data,))\n    File \"c:\\Users\\ASUS\\AppData\\Local\\Programs\\Python\\Python39\\lib\\site-packages\\keras\\engine\\training.py\", line 1135, in run_step\n      outputs = model.train_step(data)\n    File \"c:\\Users\\ASUS\\AppData\\Local\\Programs\\Python\\Python39\\lib\\site-packages\\keras\\engine\\training.py\", line 993, in train_step\n      y_pred = self(x, training=True)\n    File \"c:\\Users\\ASUS\\AppData\\Local\\Programs\\Python\\Python39\\lib\\site-packages\\keras\\utils\\traceback_utils.py\", line 65, in error_handler\n      return fn(*args, **kwargs)\n    File \"c:\\Users\\ASUS\\AppData\\Local\\Programs\\Python\\Python39\\lib\\site-packages\\keras\\engine\\training.py\", line 557, in __call__\n      return super().__call__(*args, **kwargs)\n    File \"c:\\Users\\ASUS\\AppData\\Local\\Programs\\Python\\Python39\\lib\\site-packages\\keras\\utils\\traceback_utils.py\", line 65, in error_handler\n      return fn(*args, **kwargs)\n    File \"c:\\Users\\ASUS\\AppData\\Local\\Programs\\Python\\Python39\\lib\\site-packages\\keras\\engine\\base_layer.py\", line 1097, in __call__\n      outputs = call_fn(inputs, *args, **kwargs)\n    File \"c:\\Users\\ASUS\\AppData\\Local\\Programs\\Python\\Python39\\lib\\site-packages\\keras\\utils\\traceback_utils.py\", line 96, in error_handler\n      return fn(*args, **kwargs)\n    File \"c:\\Users\\ASUS\\AppData\\Local\\Programs\\Python\\Python39\\lib\\site-packages\\keras\\engine\\sequential.py\", line 410, in call\n      return super().call(inputs, training=training, mask=mask)\n    File \"c:\\Users\\ASUS\\AppData\\Local\\Programs\\Python\\Python39\\lib\\site-packages\\keras\\engine\\functional.py\", line 510, in call\n      return self._run_internal_graph(inputs, training=training, mask=mask)\n    File \"c:\\Users\\ASUS\\AppData\\Local\\Programs\\Python\\Python39\\lib\\site-packages\\keras\\engine\\functional.py\", line 667, in _run_internal_graph\n      outputs = node.layer(*args, **kwargs)\n    File \"c:\\Users\\ASUS\\AppData\\Local\\Programs\\Python\\Python39\\lib\\site-packages\\keras\\utils\\traceback_utils.py\", line 65, in error_handler\n      return fn(*args, **kwargs)\n    File \"c:\\Users\\ASUS\\AppData\\Local\\Programs\\Python\\Python39\\lib\\site-packages\\keras\\engine\\training.py\", line 557, in __call__\n      return super().__call__(*args, **kwargs)\n    File \"c:\\Users\\ASUS\\AppData\\Local\\Programs\\Python\\Python39\\lib\\site-packages\\keras\\utils\\traceback_utils.py\", line 65, in error_handler\n      return fn(*args, **kwargs)\n    File \"c:\\Users\\ASUS\\AppData\\Local\\Programs\\Python\\Python39\\lib\\site-packages\\keras\\engine\\base_layer.py\", line 1097, in __call__\n      outputs = call_fn(inputs, *args, **kwargs)\n    File \"c:\\Users\\ASUS\\AppData\\Local\\Programs\\Python\\Python39\\lib\\site-packages\\keras\\utils\\traceback_utils.py\", line 96, in error_handler\n      return fn(*args, **kwargs)\n    File \"c:\\Users\\ASUS\\AppData\\Local\\Programs\\Python\\Python39\\lib\\site-packages\\keras\\engine\\functional.py\", line 510, in call\n      return self._run_internal_graph(inputs, training=training, mask=mask)\n    File \"c:\\Users\\ASUS\\AppData\\Local\\Programs\\Python\\Python39\\lib\\site-packages\\keras\\engine\\functional.py\", line 667, in _run_internal_graph\n      outputs = node.layer(*args, **kwargs)\n    File \"c:\\Users\\ASUS\\AppData\\Local\\Programs\\Python\\Python39\\lib\\site-packages\\keras\\utils\\traceback_utils.py\", line 65, in error_handler\n      return fn(*args, **kwargs)\n    File \"c:\\Users\\ASUS\\AppData\\Local\\Programs\\Python\\Python39\\lib\\site-packages\\keras\\engine\\base_layer.py\", line 1097, in __call__\n      outputs = call_fn(inputs, *args, **kwargs)\n    File \"c:\\Users\\ASUS\\AppData\\Local\\Programs\\Python\\Python39\\lib\\site-packages\\keras\\utils\\traceback_utils.py\", line 96, in error_handler\n      return fn(*args, **kwargs)\n    File \"c:\\Users\\ASUS\\AppData\\Local\\Programs\\Python\\Python39\\lib\\site-packages\\keras\\layers\\convolutional\\base_conv.py\", line 314, in call\n      return self.activation(outputs)\n    File \"c:\\Users\\ASUS\\AppData\\Local\\Programs\\Python\\Python39\\lib\\site-packages\\keras\\activations.py\", line 317, in relu\n      return backend.relu(\n    File \"c:\\Users\\ASUS\\AppData\\Local\\Programs\\Python\\Python39\\lib\\site-packages\\keras\\backend.py\", line 5366, in relu\n      x = tf.nn.relu(x)\nNode: 'sequential_5/vgg16/block4_conv2/Relu'\nOOM when allocating tensor with shape[8,512,28,28] and type float on /job:localhost/replica:0/task:0/device:GPU:0 by allocator GPU_0_bfc\n\t [[{{node sequential_5/vgg16/block4_conv2/Relu}}]]\nHint: If you want to see a list of allocated tensors when OOM happens, add report_tensor_allocations_upon_oom to RunOptions for current allocation info. This isn't available when running in Eager mode.\n [Op:__inference_train_function_12109]"
     ]
    }
   ],
   "source": [
    "import tensorflow as tf\n",
    "from tensorflow.keras.applications import VGG16\n",
    "from tensorflow.keras.layers import Flatten, Dense\n",
    "\n",
    "import tensorflow as tf\n",
    "\n",
    "# Set GPU memory growth before initializing GPU devices\n",
    "gpus = tf.config.experimental.list_physical_devices('GPU')\n",
    "\n",
    "if gpus:\n",
    "    try:\n",
    "        for gpu in gpus:\n",
    "            tf.config.experimental.set_memory_growth(gpu, True)\n",
    "    except RuntimeError as e:\n",
    "        print(e)\n",
    "else:\n",
    "    print(\"No GPU devices found\")\n",
    "\n",
    "\n",
    "\n",
    "# Load the training and test data\n",
    "train_data = tf.keras.preprocessing.image_dataset_from_directory(\n",
    "    \"train\",\n",
    "    labels=\"inferred\",\n",
    "    label_mode=\"categorical\",\n",
    "    batch_size=8,\n",
    "    image_size=(224, 224),\n",
    ")\n",
    "\n",
    "test_data = tf.keras.preprocessing.image_dataset_from_directory(\n",
    "    \"test\",\n",
    "    labels=\"inferred\",\n",
    "    label_mode=\"categorical\",\n",
    "    batch_size=8,\n",
    "    image_size=(224, 224),\n",
    ")\n",
    "\n",
    "# Define the base VGG16 model\n",
    "base_model = VGG16(\n",
    "    weights=\"imagenet\",\n",
    "    include_top=False,\n",
    "    input_shape=(224, 224, 3),\n",
    ")\n",
    "\n",
    "# Create a new model by specifying the input and output layers\n",
    "model = tf.keras.Sequential()\n",
    "model.add(base_model)  # Add the VGG16 base model\n",
    "\n",
    "# Add a Flatten layer\n",
    "model.add(Flatten())\n",
    "\n",
    "# Add a Dense classification layer\n",
    "model.add(Dense(24, activation=\"softmax\"))\n",
    "\n",
    "# Compile the model\n",
    "model.compile(\n",
    "    optimizer=\"adam\",\n",
    "    loss=\"categorical_crossentropy\",\n",
    "    metrics=[\"accuracy\"],\n",
    ")\n",
    "\n",
    "# Train the model\n",
    "model.fit(train_data, epochs=10)\n",
    "\n",
    "# Evaluate the model\n",
    "test_loss, test_accuracy = model.evaluate(test_data)\n",
    "\n",
    "# Print the test accuracy\n",
    "print(\"Test accuracy:\", test_accuracy)\n"
   ]
  },
  {
   "cell_type": "code",
   "execution_count": null,
   "metadata": {},
   "outputs": [],
   "source": []
  },
  {
   "cell_type": "code",
   "execution_count": null,
   "metadata": {},
   "outputs": [],
   "source": []
  },
  {
   "cell_type": "code",
   "execution_count": null,
   "metadata": {},
   "outputs": [],
   "source": []
  },
  {
   "cell_type": "code",
   "execution_count": null,
   "metadata": {},
   "outputs": [],
   "source": []
  },
  {
   "cell_type": "code",
   "execution_count": null,
   "metadata": {},
   "outputs": [],
   "source": []
  },
  {
   "cell_type": "code",
   "execution_count": null,
   "metadata": {},
   "outputs": [],
   "source": []
  },
  {
   "cell_type": "code",
   "execution_count": null,
   "metadata": {},
   "outputs": [
    {
     "name": "stdout",
     "output_type": "stream",
     "text": [
      "GPU device: /physical_device:GPU:0\n"
     ]
    }
   ],
   "source": [
    "import tensorflow as tf\n",
    "\n",
    "# Get a list of all available GPU devices\n",
    "physical_devices = tf.config.experimental.list_physical_devices('GPU')\n",
    "\n",
    "# Print the list of GPU devices\n",
    "if len(physical_devices) > 0:\n",
    "    for gpu in physical_devices:\n",
    "        print(\"GPU device:\", gpu.name)\n",
    "else:\n",
    "    print(\"No GPU devices found.\")\n"
   ]
  },
  {
   "cell_type": "code",
   "execution_count": null,
   "metadata": {},
   "outputs": [],
   "source": []
  },
  {
   "cell_type": "code",
   "execution_count": null,
   "metadata": {},
   "outputs": [],
   "source": []
  },
  {
   "cell_type": "code",
   "execution_count": null,
   "metadata": {},
   "outputs": [],
   "source": []
  },
  {
   "cell_type": "code",
   "execution_count": null,
   "metadata": {},
   "outputs": [],
   "source": []
  },
  {
   "cell_type": "code",
   "execution_count": null,
   "metadata": {},
   "outputs": [],
   "source": []
  },
  {
   "cell_type": "code",
   "execution_count": null,
   "metadata": {},
   "outputs": [],
   "source": []
  },
  {
   "cell_type": "code",
   "execution_count": null,
   "metadata": {},
   "outputs": [],
   "source": []
  },
  {
   "cell_type": "code",
   "execution_count": null,
   "metadata": {},
   "outputs": [],
   "source": []
  },
  {
   "cell_type": "code",
   "execution_count": null,
   "metadata": {},
   "outputs": [],
   "source": []
  },
  {
   "cell_type": "code",
   "execution_count": null,
   "metadata": {},
   "outputs": [],
   "source": []
  },
  {
   "cell_type": "code",
   "execution_count": null,
   "metadata": {},
   "outputs": [],
   "source": []
  }
 ],
 "metadata": {
  "kernelspec": {
   "display_name": "Python 3",
   "language": "python",
   "name": "python3"
  },
  "language_info": {
   "codemirror_mode": {
    "name": "ipython",
    "version": 3
   },
   "file_extension": ".py",
   "mimetype": "text/x-python",
   "name": "python",
   "nbconvert_exporter": "python",
   "pygments_lexer": "ipython3",
   "version": "3.9.12"
  },
  "orig_nbformat": 4
 },
 "nbformat": 4,
 "nbformat_minor": 2
}
